<?xml version="1.0"?>
<!-- Copyright (c) 2016 The UUV Simulator Authors.
     All rights reserved.

     Licensed under the Apache License, Version 2.0 (the "License");
     you may not use this file except in compliance with the License.
     You may obtain a copy of the License at

       http://www.apache.org/licenses/LICENSE-2.0

     Unless required by applicable law or agreed to in writing, software
     distributed under the License is distributed on an "AS IS" BASIS,
     WITHOUT WARRANTIES OR CONDITIONS OF ANY KIND, either express or implied.
     See the License for the specific language governing permissions and
     limitations under the License.
-->
<robot xmlns:xacro="http://www.ros.org/wiki/xacro" >
  <!-- Import macro files -->
  <xacro:include filename="$(find uuv_descriptions)/urdf/common.urdf.xacro" />
  <xacro:include filename="$(find uuv_sensor_ros_plugins)/urdf/sensor_snippets.xacro"/>
  <xacro:include filename="$(find glider_hybrid_whoi_description)/urdf/glider_hybrid_whoi_snippets_test.xacro"/>
  <xacro:include filename="$(find uuv_gazebo_ros_plugins)/urdf/snippets.xacro"/>

  <!-- Properties -->
  <xacro:property name="mass" value="10000.0"/>
  
  <xacro:property name="visual_mesh_file" value="file://$(find glider_hybrid_whoi_description)/mesh/glider_hybrid_whoi/glider_hybrid_whoi_body.dae" />
  <xacro:property name="collision_mesh_file" value="file://$(find glider_hybrid_whoi_description)/mesh/glider_hybrid_whoi/glider_hybrid_whoi_collision.dae" />
  <xacro:property name="left_prop_mesh_file" value="file://$(find glider_hybrid_whoi_description)/mesh/glider_hybrid_whoi/glider_hybrid_whoi_left_propeller.dae" />
  <xacro:property name="right_prop_mesh_file" value="file://$(find glider_hybrid_whoi_description)/mesh/glider_hybrid_whoi/glider_hybrid_whoi_right_propeller.dae" />

  <xacro:macro name="glider_hybrid_whoi_base" params="namespace debug inertial_reference_frame">
    <link name="${namespace}/base_link">
      <visual>
        <origin xyz="0 0 0" rpy="0 0 -${0.5*pi}" />
        <geometry>
          <mesh filename="${visual_mesh_file}" scale="1 1 1" />
        </geometry>
      </visual>
      <collision>
        <origin xyz="0 0 0" rpy="0 0 -${0.5*pi}" />
        <geometry>
          <mesh filename="${collision_mesh_file}" scale="1 1 1" />
        </geometry>
      </collision>
      <inertial>
        <mass value="${mass}"/>
        <origin xyz="0 0 0" rpy="0 0 0" />
        <inertia ixx="30.0" ixy="0" ixz="0" iyy="0.6" iyz="0" izz="5.0" />
      </inertial>
    </link>

  <xacro:property name="thruster_id" value="1"/>
    <joint name="${namespace}/thruster_${thruster_id}_joint" type="continuous">
      <origin xyz="-0.558 -0.05 0" rpy="0 0 -${0.07*pi}"/>
      <axis xyz="1 0 0"/>
      <parent link="${namespace}/base_link"/>
      <child link="${namespace}/thruster_${thruster_id}"/>
    </joint>

    <link name="${namespace}/thruster_${thruster_id}">
      <xacro:box_inertial x="0" y="0" z="0" mass="0.00001">
        <origin xyz="0 0 0" rpy="0 0 0"/>
      </xacro:box_inertial>
      <visual>
        <origin xyz="0.541 0.12 0" rpy="0 0 -${0.46*pi}"/>
        <geometry>
          <mesh filename="${right_prop_mesh_file}" scale="1 1 1"/>
        </geometry>
      </visual>
      <collision>
        <geometry>
          <cylinder length="0.000001" radius="0.000001"/>
        </geometry>
        <origin xyz="0 0 0" rpy="0 0 0"/>
      </collision>
    </link>

    <gazebo>
      <plugin name="${namespace}_${thruster_id}_thruster_model" filename="libuuv_thruster_ros_plugin.so">
        <linkName>${namespace}/thruster_${thruster_id}</linkName>
        <jointName>${namespace}/thruster_${thruster_id}_joint</jointName>
        <thrusterID>${thruster_id}</thrusterID>
        <dynamics>
          <type>FirstOrder</type>
          <timeConstant>0.0</timeConstant>
        </dynamics>
        <conversion>
          <type>Basic</type>
          <rotorConstant>0.0</rotorConstant>
        </conversion>
      </plugin>
    </gazebo>
    <gazebo reference="${namespace}/thruster_${thruster_id}">
      <selfCollide>false</selfCollide>
    </gazebo>

    <xacro:property name="thruster_id" value="0"/>
    <joint name="${namespace}/thruster_${thruster_id}_joint" type="continuous">
      <origin xyz="-0.558 0.05 0" rpy="0 0 ${0.07*pi+pi}"/>
      <axis xyz="1 0 0"/>
      <parent link="${namespace}/base_link"/>
      <child link="${namespace}/thruster_${thruster_id}"/>
    </joint>

    <link name="${namespace}/thruster_${thruster_id}">
      <xacro:box_inertial x="0" y="0" z="0" mass="0.00001">
        <origin xyz="0 0 0" rpy="0 0 0"/>
      </xacro:box_inertial>
      <visual>
        <origin xyz="-0.541 0.12 0" rpy="0 0 ${0.46*pi}"/>
        <geometry>
          <mesh filename="${left_prop_mesh_file}" scale="1 1 1"/>
        </geometry>
      </visual>
      <collision>
        <geometry>
          <cylinder length="0.000001" radius="0.000001"/>
        </geometry>
        <origin xyz="0 0 0" rpy="0 0 0"/>
      </collision>
    </link>

    <gazebo>
      <plugin name="${namespace}_${thruster_id}_thruster_model" filename="libuuv_thruster_ros_plugin.so">
        <linkName>${namespace}/thruster_${thruster_id}</linkName>
        <jointName>${namespace}/thruster_${thruster_id}_joint</jointName>
        <thrusterID>${thruster_id}</thrusterID>
        <dynamics>
          <type>FirstOrder</type>
          <timeConstant>0.0</timeConstant>
        </dynamics>
        <conversion>
          <type>Basic</type>
          <rotorConstant>0.0</rotorConstant>
        </conversion>
      </plugin>
    </gazebo>
    <gazebo reference="${namespace}/thruster_${thruster_id}">
      <selfCollide>false</selfCollide>
    </gazebo>

    <!-- Set up hydrodynamic plugin -->
    <gazebo>
      <plugin name="${namespace}_direct_kinematics_plugin"
              filename="libdirect_kinematics_ros_plugin.so">
        <writeLog>1</writeLog>
      </plugin>
    </gazebo>

    <!-- TODO: Parametrize the battery unit -->
    <xacro:basic_linear_battery_macro
      namespace="${namespace}"
      parent_link="${namespace}/base_link"
      prefix=""
      open_circuit_voltage_constant_coef="3.7"
      open_circuit_voltage_linear_coef="-3.1424"
      initial_charge="1.1665"
      capacity="0.5"
      resistance="0.002"
      smooth_current_tau="1.9499"
      voltage="4.2"
      update_rate="2.0"/>

    <xacro:include filename="$(find glider_hybrid_whoi_description)/urdf/glider_hybrid_whoi_sensors_kinematics.xacro"/>
  </xacro:macro>
</robot>
